Traceback (most recent call last):
  File "/home/julian/.local/lib/python3.10/site-packages/jupyter_cache/executors/utils.py", line 58, in single_nb_execution
    executenb(
  File "/usr/lib/python3/dist-packages/nbclient/client.py", line 1093, in execute
    return NotebookClient(nb=nb, resources=resources, km=km, **kwargs).execute()
  File "/usr/lib/python3/dist-packages/nbclient/util.py", line 84, in wrapped
    return just_run(coro(*args, **kwargs))
  File "/usr/lib/python3/dist-packages/nbclient/util.py", line 62, in just_run
    return loop.run_until_complete(coro)
  File "/usr/lib/python3.10/asyncio/base_events.py", line 646, in run_until_complete
    return future.result()
  File "/usr/lib/python3/dist-packages/nbclient/client.py", line 559, in async_execute
    await self.async_execute_cell(
  File "/usr/lib/python3/dist-packages/nbclient/client.py", line 854, in async_execute_cell
    self._check_raise_for_error(cell, exec_reply)
  File "/usr/lib/python3/dist-packages/nbclient/client.py", line 756, in _check_raise_for_error
    raise CellExecutionError.from_cell_and_msg(cell, exec_reply_content)
nbclient.exceptions.CellExecutionError: An error occurred while executing the following cell:
------------------
#SELECT Note
#FROM PrÃ¼ft
#WHERE Matrikel = â€˜123456â€˜
#AND Note >= ALL (SELECT Note
#                 FROM PrÃ¼ft
#                 WHERE Matrikel = â€˜123456â€˜)

__SQL__ = "SELECT Note FROM Prueft WHERE Matrikel = â€˜123456â€˜ AND Note >= ALL (SELECT Note FROM Prueft WHERE Matrikel = â€˜123456â€˜)"
conn = sqlite3.connect("lehre/lehre.db")
df = pd.read_sql_query(__SQL__, conn)
df
------------------

[0;31m---------------------------------------------------------------------------[0m
[0;31mOperationalError[0m                          Traceback (most recent call last)
[0;32m~/.local/lib/python3.10/site-packages/pandas/io/sql.py[0m in [0;36mexecute[0;34m(self, sql, params)[0m
[1;32m   2201[0m         [0;32mtry[0m[0;34m:[0m[0;34m[0m[0;34m[0m[0m
[0;32m-> 2202[0;31m             [0mcur[0m[0;34m.[0m[0mexecute[0m[0;34m([0m[0msql[0m[0;34m,[0m [0;34m*[0m[0margs[0m[0;34m)[0m[0;34m[0m[0;34m[0m[0m
[0m[1;32m   2203[0m             [0;32mreturn[0m [0mcur[0m[0;34m[0m[0;34m[0m[0m

[0;31mOperationalError[0m: near "ALL": syntax error

The above exception was the direct cause of the following exception:

[0;31mDatabaseError[0m                             Traceback (most recent call last)
[0;32m/tmp/ipykernel_11992/220724098.py[0m in [0;36m<module>[0;34m[0m
[1;32m      8[0m [0m__SQL__[0m [0;34m=[0m [0;34m"SELECT Note FROM Prueft WHERE Matrikel = â€˜123456â€˜ AND Note >= ALL (SELECT Note FROM Prueft WHERE Matrikel = â€˜123456â€˜)"[0m[0;34m[0m[0;34m[0m[0m
[1;32m      9[0m [0mconn[0m [0;34m=[0m [0msqlite3[0m[0;34m.[0m[0mconnect[0m[0;34m([0m[0;34m"lehre/lehre.db"[0m[0;34m)[0m[0;34m[0m[0;34m[0m[0m
[0;32m---> 10[0;31m [0mdf[0m [0;34m=[0m [0mpd[0m[0;34m.[0m[0mread_sql_query[0m[0;34m([0m[0m__SQL__[0m[0;34m,[0m [0mconn[0m[0;34m)[0m[0;34m[0m[0;34m[0m[0m
[0m[1;32m     11[0m [0mdf[0m[0;34m[0m[0;34m[0m[0m

[0;32m~/.local/lib/python3.10/site-packages/pandas/io/sql.py[0m in [0;36mread_sql_query[0;34m(sql, con, index_col, coerce_float, params, parse_dates, chunksize, dtype, dtype_backend)[0m
[1;32m    467[0m [0;34m[0m[0m
[1;32m    468[0m     [0;32mwith[0m [0mpandasSQL_builder[0m[0;34m([0m[0mcon[0m[0;34m)[0m [0;32mas[0m [0mpandas_sql[0m[0;34m:[0m[0;34m[0m[0;34m[0m[0m
[0;32m--> 469[0;31m         return pandas_sql.read_query(
[0m[1;32m    470[0m             [0msql[0m[0;34m,[0m[0;34m[0m[0;34m[0m[0m
[1;32m    471[0m             [0mindex_col[0m[0;34m=[0m[0mindex_col[0m[0;34m,[0m[0;34m[0m[0;34m[0m[0m

[0;32m~/.local/lib/python3.10/site-packages/pandas/io/sql.py[0m in [0;36mread_query[0;34m(self, sql, index_col, coerce_float, parse_dates, params, chunksize, dtype, dtype_backend)[0m
[1;32m   2264[0m         [0mdtype_backend[0m[0;34m:[0m [0mDtypeBackend[0m [0;34m|[0m [0mLiteral[0m[0;34m[[0m[0;34m"numpy"[0m[0;34m][0m [0;34m=[0m [0;34m"numpy"[0m[0;34m,[0m[0;34m[0m[0;34m[0m[0m
[1;32m   2265[0m     ) -> DataFrame | Iterator[DataFrame]:
[0;32m-> 2266[0;31m         [0mcursor[0m [0;34m=[0m [0mself[0m[0;34m.[0m[0mexecute[0m[0;34m([0m[0msql[0m[0;34m,[0m [0mparams[0m[0;34m)[0m[0;34m[0m[0;34m[0m[0m
[0m[1;32m   2267[0m         [0mcolumns[0m [0;34m=[0m [0;34m[[0m[0mcol_desc[0m[0;34m[[0m[0;36m0[0m[0;34m][0m [0;32mfor[0m [0mcol_desc[0m [0;32min[0m [0mcursor[0m[0;34m.[0m[0mdescription[0m[0;34m][0m[0;34m[0m[0;34m[0m[0m
[1;32m   2268[0m [0;34m[0m[0m

[0;32m~/.local/lib/python3.10/site-packages/pandas/io/sql.py[0m in [0;36mexecute[0;34m(self, sql, params)[0m
[1;32m   2212[0m [0;34m[0m[0m
[1;32m   2213[0m             [0mex[0m [0;34m=[0m [0mDatabaseError[0m[0;34m([0m[0;34mf"Execution failed on sql '{sql}': {exc}"[0m[0;34m)[0m[0;34m[0m[0;34m[0m[0m
[0;32m-> 2214[0;31m             [0;32mraise[0m [0mex[0m [0;32mfrom[0m [0mexc[0m[0;34m[0m[0;34m[0m[0m
[0m[1;32m   2215[0m [0;34m[0m[0m
[1;32m   2216[0m     [0;34m@[0m[0mstaticmethod[0m[0;34m[0m[0;34m[0m[0m

[0;31mDatabaseError[0m: Execution failed on sql 'SELECT Note FROM Prueft WHERE Matrikel = â€˜123456â€˜ AND Note >= ALL (SELECT Note FROM Prueft WHERE Matrikel = â€˜123456â€˜)': near "ALL": syntax error
DatabaseError: Execution failed on sql 'SELECT Note FROM Prueft WHERE Matrikel = â€˜123456â€˜ AND Note >= ALL (SELECT Note FROM Prueft WHERE Matrikel = â€˜123456â€˜)': near "ALL": syntax error

